"""
Error Handling with Constitutional AI Tiers
Following ERROR_HANDLING_TIERS.md protocol
"""

import time
import logging
import asyncio
from typing import Any, Callable, Optional

logger = logging.getLogger(__name__)

class TierHandler:
    """Implements Tier 1-4 error handling for autonomous recovery"""
    
    def __init__(self):
        self.tier_config = {
            1: {"retries": 1, "immediate": True, "continue_on_fail": True},
            2: {"retries": 3, "backoff": True, "workaround": True},
            3: {"workaround": True, "document": True, "degrade": True},
            4: {"recovery_plan": True, "handoff": True, "alert": True}
        }
        
    async def handle_error(self, error: Exception, context: dict) -> Any:
        """Automatically handle errors based on tier classification"""
        tier = self._classify_error(error)
        logger.info(f"âš¡ Tier {tier} error handling activated - Maximum Velocity Mode")
        
        if tier == 1:
            return await self._tier1_handler(error, context)
        elif tier == 2:
            return await self._tier2_handler(error, context)
        elif tier == 3:
            return await self._tier3_handler(error, context)
        else:
            return await self._tier4_handler(error, context)
    
    def _classify_error(self, error: Exception) -> int:
        """Classify error into appropriate tier"""
        error_str = str(error).lower()
        
        # Tier 1: Transient issues
        if any(x in error_str for x in ['timeout', 'temporary', 'connection reset']):
            return 1
        
        # Tier 2: Persistent issues
        if any(x in error_str for x in ['permission', 'resource', 'rate limit']):
            return 2
            
        # Tier 3: System issues
        if any(x in error_str for x in ['service unavailable', 'dependency']):
            return 3
            
        # Tier 4: Critical failures
        return 4
        
    async def _tier1_handler(self, error: Exception, context: dict) -> Any:
        """Tier 1: Retry once and continue"""
        logger.info("Tier 1: Retrying once immediately...")
        try:
            return await context['function']()
        except:
            logger.info("Tier 1: Retry failed, continuing with workflow...")
            return context.get('fallback_value')
            
    async def _tier2_handler(self, error: Exception, context: dict) -> Any:
        """Tier 2: Multiple retries with backoff"""
        for i in range(3):
            await asyncio.sleep(2 ** i)  # Exponential backoff
            try:
                return await context['function']()
            except:
                continue
        
        # Implement workaround
        logger.info("Tier 2: Implementing workaround...")
        return await context.get('workaround_function', lambda: None)()
        
    async def _tier3_handler(self, error: Exception, context: dict) -> Any:
        """Tier 3: Degrade gracefully with workaround"""
        logger.warning(f"Tier 3: System issue detected - {error}")
        
        # Document the issue
        self._document_issue(error, context)
        
        # Implement degraded mode
        logger.info("Tier 3: Operating in degraded mode...")
        return await context.get('degraded_function', lambda: None)()
        
    async def _tier4_handler(self, error: Exception, context: dict) -> Any:
        """Tier 4: Generate recovery plan"""
        logger.error(f"Tier 4: Critical failure - {error}")
        
        recovery_plan = {
            "error": str(error),
            "context": context,
            "recovery_steps": [
                "1. Check system resources",
                "2. Verify all dependencies",
                "3. Review recent changes",
                "4. Implement rollback if needed"
            ],
            "handoff_ready": True
        }
        
        self._save_recovery_plan(recovery_plan)
        logger.info("Tier 4: Recovery plan generated, system continuing with limitations")
        
        return None
        
    def _document_issue(self, error: Exception, context: dict):
        """Document issue for future reference"""
        # Store in PIECES for pattern recognition
        pass
        
    def _save_recovery_plan(self, plan: dict):
        """Save recovery plan for handoff"""
        # Save to file or database
        pass